Workbook

Sheet Resumen
A1: CENSO SNACKS MB — HORMIGA NEGRA
A2: Resumen ejecutivo del análisis (base = 2.883 PDV activos en la categoría)
A4: PARÁMETROS Y SUPUESTOS
A5: Umbral Potencial Alto (Pareto, corte ~70% del volumen) | B5: 40 | D5: Def.: PDV ordenados por Potencial Pdv desc. El corte que acumula el 70% del volumen total cae en 40 unidades/semana (730 PDV, 25,3% de la base, concentran 72,9% del volumen).
A6: Tolerancia sobre/sub-exhibición (puntos porcentuales) | B6: 0.05 | D6: Diferencia mínima entre % de frentes y % de share de volumen para considerar sobre/sub-exhibido.
A7: PTR Lays (precio de compra del PDV, fijo) | B7: 2500 | D7: Dato provisto por Fabian: precio de compra único para todos los PDV (a diferencia de Quento/Julicroc, que varía por PDV).
A8: Umbral mínimo de diferencia de markup para activar el plan de baja | B8: 0.04 | D8: Solo se marca oportunidad si Markup Lays supera al de la competencia por más de este umbral (ej: 44% vs 40% = 4pp, no alcanza).
A9: DISTRIBUCIÓN FÍSICA
A10: Total PDV analizados (base final) | B10: =COUNTA('Base PDV'!$A$2:$A$2884) -> 2883
A11: Vende Lays | B11: =COUNTIF('Base PDV'!$P$2:$P$2884,"Sí") -> 2795
A12: % sobre el total | B12: =B11/B10 -> 0.96947624
A13: Vende Competencia (Quento y/o Julicroc) | B13: =COUNTIF('Base PDV'!$Q$2:$Q$2884,"Sí") -> 1415
A14: % sobre el total | B14: =B13/B10 -> 0.49080819
A15: de los cuales, vende Quento | B15: =COUNTIF('Base PDV'!$N$2:$N$2884,"Sí") -> 1415
A16: de los cuales, vende Julicroc | B16: =COUNTIF('Base PDV'!$O$2:$O$2884,"Sí") -> 909
A17: Conviven (Lays + Competencia) | B17: =COUNTIFS('Base PDV'!$P$2:$P$2884,"Sí",'Base PDV'!$Q$2:$Q$2884,"Sí") -> 1327
A18: Solo Lays (sin competencia) | B18: =COUNTIFS('Base PDV'!$P$2:$P$2884,"Sí",'Base PDV'!$Q$2:$Q$2884,"No") -> 1468
A19: Solo Competencia (sin Lays) | B19: =COUNTIFS('Base PDV'!$P$2:$P$2884,"No",'Base PDV'!$Q$2:$Q$2884,"Sí") -> 88
A21: POTENCIAL DE MERCADO Y PARETO
A22: Potencial total de mercado (unid./semana) | B22: =SUM('Base PDV'!$M$2:$M$2884) -> 72577.7
A23: PDV de Alto Potencial (Pareto) | B23: =COUNTIF('Base PDV'!$AP$2:$AP$2884,"Alto") -> 730
A24: % de PDV | B24: =B23/B10 -> 0.25320846
A25: % del volumen que concentran | B25: =SUMIF('Base PDV'!$AP$2:$AP$2884,"Alto",'Base PDV'!$M$2:$M$2884)/B22 -> 0.7294596
A27: SHARE (NOSOTROS = LAYS)
A28: Share Total (Lays / Potencial, todos los PDV) | B28: =SUM('Base PDV'!$K$2:$K$2884)/SUM('Base PDV'!$M$2:$M$2884) -> 0.38873786
A29: Corte Alto Share en Competencia (definido por Fabian) | B29: 0.5 | D29: Corte de negocio a 50% de SOM (en vez del promedio observado, ver referencia debajo) — más simple de comunicar al equipo comercial.
A30: Share real promedio en Competencia (referencia, dato observado) | B30: =SUMIF('Base PDV'!$Q$2:$Q$2884,"Sí",'Base PDV'!$K$2:$K$2884)/SUMIF('Base PDV'!$Q$2:$Q$2884,"Sí",'Base PDV'!$M$2:$M$2884) -> 0.36099788
A31: CUADRANTES — Potencial x Share Total (todos los PDV)
A32: Cuadrante | B32: PDV | C32: % PDV | D32: Volumen (Potencial) | E32: % Volumen
A33: Alto Potencial / Alto Share | B33: =COUNTIF('Base PDV'!$AR$2:$AR$2884,A33) -> 347 | C33: =B33/$B$10 -> 0.12036074 | D33: =SUMIF('Base PDV'!$AR$2:$AR$2884,A33,'Base PDV'!$M$2:$M$2884) -> 27551.5 | E33: =D33/$B$22 -> 0.37961385
A34: Alto Potencial / Bajo Share | B34: =COUNTIF('Base PDV'!$AR$2:$AR$2884,A34) -> 383 | C34: =B34/$B$10 -> 0.13284773 | D34: =SUMIF('Base PDV'!$AR$2:$AR$2884,A34,'Base PDV'!$M$2:$M$2884) -> 25391 | E34: =D34/$B$22 -> 0.34984575
A35: Bajo Potencial / Alto Share | B35: =COUNTIF('Base PDV'!$AR$2:$AR$2884,A35) -> 1606 | C35: =B35/$B$10 -> 0.55705862 | D35: =SUMIF('Base PDV'!$AR$2:$AR$2884,A35,'Base PDV'!$M$2:$M$2884) -> 6604.2 | E35: =D35/$B$22 -> 0.090994892
A36: Bajo Potencial / Bajo Share | B36: =COUNTIF('Base PDV'!$AR$2:$AR$2884,A36) -> 547 | C36: =B36/$B$10 -> 0.18973292 | D36: =SUMIF('Base PDV'!$AR$2:$AR$2884,A36,'Base PDV'!$M$2:$M$2884) -> 13031 | E36: =D36/$B$22 -> 0.17954551
A38: CUADRANTES — Potencial x Share en Competencia (solo PDV donde vende la competencia)
A39: Cuadrante | B39: PDV | C39: % PDV | D39: Volumen (Potencial) | E39: % Volumen
A40: Alto Potencial / Alto Share | B40: =COUNTIF('Base PDV'!$AT$2:$AT$2884,A40) -> 186 | C40: =B40/COUNTIF('Base PDV'!$Q$2:$Q$2884,"Sí") -> 0.13144876 | D40: =SUMIF('Base PDV'!$AT$2:$AT$2884,A40,'Base PDV'!$M$2:$M$2884) -> 15236 | E40: =D40/SUMIF('Base PDV'!$Q$2:$Q$2884,"Sí",'Base PDV'!$M$2:$M$2884) -> 0.21945353
A41: Alto Potencial / Bajo Share | B41: =COUNTIF('Base PDV'!$AT$2:$AT$2884,A41) -> 540 | C41: =B41/COUNTIF('Base PDV'!$Q$2:$Q$2884,"Sí") -> 0.38162544 | D41: =SUMIF('Base PDV'!$AT$2:$AT$2884,A41,'Base PDV'!$M$2:$M$2884) -> 37427 | E41: =D41/SUMIF('Base PDV'!$Q$2:$Q$2884,"Sí",'Base PDV'!$M$2:$M$2884) -> 0.53908422
A42: Bajo Potencial / Alto Share | B42: =COUNTIF('Base PDV'!$AT$2:$AT$2884,A42) -> 60 | C42: =B42/COUNTIF('Base PDV'!$Q$2:$Q$2884,"Sí") -> 0.042402827 | D42: =SUMIF('Base PDV'!$AT$2:$AT$2884,A42,'Base PDV'!$M$2:$M$2884) -> 1486 | E42: =D42/SUMIF('Base PDV'!$Q$2:$Q$2884,"Sí",'Base PDV'!$M$2:$M$2884) -> 0.021403777
A43: Bajo Potencial / Bajo Share | B43: =COUNTIF('Base PDV'!$AT$2:$AT$2884,A43) -> 629 | C43: =B43/COUNTIF('Base PDV'!$Q$2:$Q$2884,"Sí") -> 0.44452297 | D43: =SUMIF('Base PDV'!$AT$2:$AT$2884,A43,'Base PDV'!$M$2:$M$2884) -> 15278 | E43: =D43/SUMIF('Base PDV'!$Q$2:$Q$2884,"Sí",'Base PDV'!$M$2:$M$2884) -> 0.22005848
A45: PRECIOS Y MARKUP
...

Sheet Base PDV
A1: Código | B1: Vendedor | C1: Zona | D1: Día | E1: Razón social | F1: Subcanal | G1: Territorio | H1: Sdv | I1: Vol. Quento | J1: Vol. Julicroc | K1: Vol. Lays | L1: Total Competencia | M1: Potencial Pdv | N1: Vende Quento (Sí/No) | O1: Vende Julicroc (Sí/No) | P1: Vende Lays (Sí/No) | Q1: Vende Competencia (Sí/No) | R1: PTR Quento | S1: PTC Quento | T1: PTR Julicroc | U1: PTC Julicroc | V1: PTC Lays | W1: Markup Quento | X1: Markup Julicroc | Y1: Markup Lays | Z1: Gap PTC Lays vs Quento | AA1: Gap % Lays vs Quento | AB1: Gap PTC Lays vs Julicroc | AC1: Gap % Lays vs Julicroc | AD1: Frentes Lays | AE1: Frentes Quento | AF1: Frentes Julicroc | AG1: Frentes Totales | AH1: Frentes Share Lays | AI1: Exhibidores PepsiCo (Lays) | AJ1: Exhibidores Quento | AK1: Exhibidores Julicroc | AL1: Tiene Exhibidor Competencia | AM1: Condición de pago Quento | AN1: Condición de pago Julicroc | AO1: Share Total (Lays/Potencial) | AP1: Alto Potencial (Pareto 70%) | AQ1: Alto Share Total | AR1: Cuadrante (Share Total) | AS1: Alto Share en Competencia | AT1: Cuadrante (Share en Competencia) | AU1: Estado Exhibición | AV1: Prioridad Cluster | AW1: Cluster Final | AX1: Gap Markup (Lays vs competencia) | AY1: Oportunidad Bajar Markup Lays | AZ1: Plan Pehuamar | BA1: Plan Combo 9+1 | BB1: Plan Aumentar Frentes | BC1: Plan Colocar Exhibidor | BD1: Plan 9+1 (con Pehuamar)
A2: 400747 | B2: 1 | C2: 101 | D2: Lunes | E2: DROVETTA CESAR JUAN DOMINGO | F2: Almacen/Despensa | G2: Santa Fe | H2: Conrado Pujol | I2: 25 | J2: 12 | K2: 15 | L2: =I2+J2 -> 37 | M2: =L2+K2 -> 52 | N2: =IF(I2>0,"Sí","No") -> Sí | O2: =IF(J2>0,"Sí","No") -> Sí | P2: =IF(K2>0,"Sí","No") -> Sí | Q2: =IF(OR(I2>0,J2>0),"Sí","No") -> Sí | R2: 2000 | S2: 2800 | T2: 1800 | U2: 2500 | V2: 3600 | W2: =IF(AND(I2>0,R2>0),(S2-R2)/R2,"") -> 0.4 | X2: =IF(AND(J2>0,T2>0),(U2-T2)/T2,"") -> 0.38888889 | Y2: =IF(AND(K2>0,V2>0),(V2-Resumen!$B$7)/Resumen!$B$7,"") -> 0.44 | Z2: =IF(AND(K2>0,I2>0,V2>0,S2>0),V2-S2,"") -> 800 | AA2: =IF(Z2<>"",Z2/S2,"") -> 0.28571429 | AB2: =IF(AND(K2>0,J2>0,V2>0,U2>0),V2-U2,"") -> 1100 | AC2: =IF(AB2<>"",AB2/U2,"") -> 0.44 | AD2: 5 | AE2: 6 | AF2: 4 | AG2: =AD2+AE2+AF2 -> 15 | AH2: =IF(AG2>0,AD2/AG2,"") -> 0.33333333 | AI2: 0 | AJ2: 0 | AK2: 0 | AL2: =IF(OR(AJ2>0,AK2>0),"Sí","No") -> No | AM2: Contado | AN2: Contado | AO2: =IF(M2>0,K2/M2,"") -> 0.28846154 | AP2: =IF(M2>=Resumen!$B$5,"Alto","Bajo") -> Alto | AQ2: =IF(AO2>=Resumen!$B$28,"Alto","Bajo") -> Bajo | AR2: =AP2&" Potencial / "&AQ2&" Share" -> Alto Potencial / Bajo Share | AS2: =IF(Q2="Sí",IF(AO2>=Resumen!$B$29,"Alto","Bajo"),"") -> Bajo | AT2: =IF(AS2<>"",AP2&" Potencial / "&AS2&" Share","") -> Alto Potencial / Bajo Share | AU2: =IF(AH2="","Sin dato",IF(AH2-AO2>Resumen!$B$6,"Sobre-exhibido",IF(AO2-AH2>Resumen!$B$6,"Sub-exhibido","En línea"))) -> En línea | AV2: =IF(AT2="","",IF(AT2="Alto Potencial / Bajo Share",1,IF(AT2="Alto Potencial / Alto Share",2,IF(AT2="Bajo Potencial / Alto Share",3,4)))) -> 1 | AW2: =IF(Q2="No","Sin competencia directa",IF(AV2=1,"1 - Foco Conquista (Alto Pot / Bajo Share)",IF(AV2=2,"2 - Foco Defensa (Alto Pot / Alto Share)",IF(AV2=3,"3 - Monitoreo (Bajo Pot / Alto Share)","4 - Baja Prioridad (Bajo Pot / Bajo Share)")))) -> 1 - Foco Conquista (Alto Pot / Bajo Share) | AX2: =IF(OR(IFERROR(AND(W2<>"",Y2<>"",Y2-W2>Resumen!$B$8),FALSE()),IFERROR(AND(X2<>"",Y2<>"",Y2-X2>Resumen!$B$8),FALSE())),MAX(IF(IFERROR(AND(W2<>"",Y2<>"",Y2-W2>Resumen!$B$8),FALSE()),Y2-W2,0),IF(IFERROR(AND(X2<>"",Y2<>"",Y2-X2>Resumen!$B$8),FALSE()),Y2-X2,0)),"") -> 0.051111111 | AY2: =IF(OR(IFERROR(AND(W2<>"",Y2<>"",Y2-W2>Resumen!$B$8),FALSE()),IFERROR(AND(X2<>"",Y2<>"",Y2-X2>Resumen!$B$8),FALSE())),TRIM("Lays tiene mayor markup que "&IF(IFERROR(AND(W2<>"",Y2<>"",Y2-W2>Resumen!$B$8),FALSE()),"Quento ","")&IF(IFERROR(AND(X2<>"",Y2<>"",Y2-X2>Resumen!$B$8),FALSE()),"Julicroc ","")&"en este PDV"),"") -> Lays tiene mayor markup que Julicroc en este PDV | AZ2: =IF(COUNTIF('Plan Pehuamar - Lista'!$A$2:$A$167,A2)>0,"Sí","No") -> No | BA2: =IF(COUNTIF('Plan Combo 9+1'!$A$2:$A$226,A2)>0,"Sí","No") -> Sí | BB2: =IF(AH2="","No",IF(BA2="Sí",IF((AO2-AH2)>Resumen!$B$6,"Sí","No"),IF((AO2-AH2)>=Resumen!$B$132,"Sí","No"))) -> No | BC2: =IF(AND(N2="Sí",AL2="Sí",AI2=0),"Sí","No") -> No | BD2: =IF(COUNTIF('Plan 9+1 (con Pehuamar)'!$A$2:$A$227,A2)>0,"Sí","No") -> Sí
A3: 400752 | B3: 1 | C3: 101 | D3: Lunes | E3: LOPEZ MARCOS FEDERICO | F3: Almacen/Despensa | G3: Santa Fe | H3: Conrado Pujol | I3: 30 | J3: 30 | K3: 20 | L3: =I3+J3 -> 60 | M3: =L3+K3 -> 80 | N3: =IF(I3>0,"Sí","No") -> Sí | O3: =IF(J3>0,"Sí","No") -> Sí | P3: =IF(K3>0,"Sí","No") -> Sí | Q3: =IF(OR(I3>0,J3>0),"Sí","No") -> Sí | R3: 2000 | S3: 3100 | T3: 1800 | U3: 2500 | V3: 3800 | W3: =IF(AND(I3>0,R3>0),(S3-R3)/R3,"") -> 0.55 | X3: =IF(AND(J3>0,T3>0),(U3-T3)/T3,"") -> 0.38888889 | Y3: =IF(AND(K3>0,V3>0),(V3-Resumen!$B$7)/Resumen!$B$7,"") -> 0.52 | Z3: =IF(AND(K3>0,I3>0,V3>0,S3>0),V3-S3,"") -> 700 | AA3: =IF(Z3<>"",Z3/S3,"") -> 0.22580645 | AB3: =IF(AND(K3>0,J3>0,V3>0,U3>0),V3-U3,"") -> 1300 | AC3: =IF(AB3<>"",AB3/U3,"") -> 0.52 | AD3: 3 | AE3: 4 | AF3: 3 | AG3: =AD3+AE3+AF3 -> 10 | AH3: =IF(AG3>0,AD3/AG3,"") -> 0.3 | AI3: 0 | AJ3: 0 | AK3: 0 | AL3: =IF(OR(AJ3>0,AK3>0),"Sí","No") -> No | AM3: Contado | AN3: Contado | AO3: =IF(M3>0,K3/M3,"") -> 0.25 | AP3: =IF(M3>=Resumen!$B$5,"Alto","Bajo") -> Alto | AQ3: =IF(AO3>=Resumen!$B$28,"Alto","Bajo") -> Bajo | AR3: =AP3&" Potencial / "&AQ3&" Share" -> Alto Potencial / Bajo Share | AS3: =IF(Q3="Sí",IF(AO3>=Resumen!$B$29,"Alto","Bajo"),"") -> Bajo | AT3: =IF(AS3<>"",AP3&" Potencial / "&AS3&" Share","") -> Alto Potencial / Bajo Share | AU3: =IF(AH3="","Sin dato",IF(AH3-AO3>Resumen!$B$6,"Sobre-exhibido",IF(AO3-AH3>Resumen!$B$6,"Sub-exhibido","En línea"))) -> En línea | AV3: =IF(AT3="","",IF(AT3="Alto Potencial / Bajo Share",1,IF(AT3="Alto Potencial / Alto Share",2,IF(AT3="Bajo Potencial / Alto Share",3,4)))) -> 1 | AW3: =IF(Q3="No","Sin competencia directa",IF(AV3=1,"1 - Foco Conquista (Alto Pot / Bajo Share)",IF(AV3=2,"2 - Foco Defensa (Alto Pot / Alto Share)",IF(AV3=3,"3 - Monitoreo (Bajo Pot / Alto Share)","4 - Baja Prioridad (Bajo Pot / Bajo Share)")))) -> 1 - Foco Conquista (Alto Pot / Bajo Share) | AX3: =IF(OR(IFERROR(AND(W3<>"",Y3<>"",Y3-W3>Resumen!$B$8),FALSE()),IFERROR(AND(X3<>"",Y3<>"",Y3-X3>Resumen!$B$8),FALSE())),MAX(IF(IFERROR(AND(W3<>"",Y3<>"",Y3-W3>Resumen!$B$8),FALSE()),Y3-W3,0),IF(IFERROR(AND(X3<>"",Y3<>"",Y3-X3>Resumen!$B$8),FALSE()),Y3-X3,0)),"") -> 0.13111111 | AY3: =IF(OR(IFERROR(AND(W3<>"",Y3<>"",Y3-W3>Resumen!$B$8),FALSE()),IFERROR(AND(X3<>"",Y3<>"",Y3-X3>Resumen!$B$8),FALSE())),TRIM("Lays tiene mayor markup que "&IF(IFERROR(AND(W3<>"",Y3<>"",Y3-W3>Resumen!$B$8),FALSE()),"Quento ","")&IF(IFERROR(AND(X3<>"",Y3<>"",Y3-X3>Resumen!$B$8),FALSE()),"Julicroc ","")&"en este PDV"),"") -> Lays tiene mayor markup que Julicroc en este PDV | AZ3: =IF(COUNTIF('Plan Pehuamar - Lista'!$A$2:$A$167,A3)>0,"Sí","No") -> No | BA3: =IF(COUNTIF('Plan Combo 9+1'!$A$2:$A$226,A3)>0,"Sí","No") -> Sí | BB3: =IF(AH3="","No",IF(BA3="Sí",IF((AO3-AH3)>Resumen!$B$6,"Sí","No"),IF((AO3-AH3)>=Resumen!$B$132,"Sí","No"))) -> No | BC3: =IF(AND(N3="Sí",AL3="Sí",AI3=0),"Sí","No") -> No | BD3: =IF(COUNTIF('Plan 9+1 (con Pehuamar)'!$A$2:$A$227,A3)>0,"Sí","No") -> Sí
A4: 400757 | B4: 1 | C4: 101 | D4: Lunes | E4: RODRIGUEZ LUCIANA MARIA FLOREN | F4: Kiosco/Maxikiosco | G4: Santa Fe | H4: Conrado Pujol | I4: 35 | J4: 30 | K4: 30 | L4: =I4+J4 -> 65 | M4: =L4+K4 -> 95 | N4: =IF(I4>0,"Sí","No") -> Sí | O4: =IF(J4>0,"Sí","No") -> Sí | P4: =IF(K4>0,"Sí","No") -> Sí | Q4: =IF(OR(I4>0,J4>0),"Sí","No") -> Sí | R4: 1900 | S4: 2700 | T4: 1700 | U4: 2600 | V4: 3600 | W4: =IF(AND(I4>0,R4>0),(S4-R4)/R4,"") -> 0.42105263 | X4: =IF(AND(J4>0,T4>0),(U4-T4)/T4,"") -> 0.52941176 | Y4: =IF(AND(K4>0,V4>0),(V4-Resumen!$B$7)/Resumen!$B$7,"") -> 0.44 | Z4: =IF(AND(K4>0,I4>0,V4>0,S4>0),V4-S4,"") -> 900 | AA4: =IF(Z4<>"",Z4/S4,"") -> 0.33333333 | AB4: =IF(AND(K4>0,J4>0,V4>0,U4>0),V4-U4,"") -> 1000 | AC4: =IF(AB4<>"",AB4/U4,"") -> 0.38461538 | AD4: 3 | AE4: 4 | AF4: 3 | AG4: =AD4+AE4+AF4 -> 10 | AH4: =IF(AG4>0,AD4/AG4,"") -> 0.3 | AI4: 0 | AJ4: 0 | AK4: 0 | AL4: =IF(OR(AJ4>0,AK4>0),"Sí","No") -> No | AM4: Contado | AN4: Contado | AO4: =IF(M4>0,K4/M4,"") -> 0.31578947 | AP4: =IF(M4>=Resumen!$B$5,"Alto","Bajo") -> Alto | AQ4: =IF(AO4>=Resumen!$B$28,"Alto","Bajo") -> Bajo | AR4: =AP4&" Potencial / "&AQ4&" Share" -> Alto Potencial / Bajo Share | AS4: =IF(Q4="Sí",IF(AO4>=Resumen!$B$29,"Alto","Bajo"),"") -> Bajo | AT4: =IF(AS4<>"",AP4&" Potencial / "&AS4&" Share","") -> Alto Potencial / Bajo Share | AU4: =IF(AH4="","Sin dato",IF(AH4-AO4>Resumen!$B$6,"Sobre-exhibido",IF(AO4-AH4>Resumen!$B$6,"Sub-exhibido","En línea"))) -> En línea | AV4: =IF(AT4="","",IF(AT4="Alto Potencial / Bajo Share",1,IF(AT4="Alto Potencial / Alto Share",2,IF(AT4="Bajo Potencial / Alto Share",3,4)))) -> 1 | AW4: =IF(Q4="No","Sin competencia directa",IF(AV4=1,"1 - Foco Conquista (Alto Pot / Bajo Share)",IF(AV4=2,"2 - Foco Defensa (Alto Pot / Alto Share)",IF(AV4=3,"3 - Monitoreo (Bajo Pot / Alto Share)","4 - Baja Prioridad (Bajo Pot / Bajo Share)")))) -> 1 - Foco Conquista (Alto Pot / Bajo Share) | AX4: =IF(OR(IFERROR(AND(W4<>"",Y4<>"",Y4-W4>Resumen!$B$8),FALSE()),IFERROR(AND(X4<>"",Y4<>"",Y4-X4>Resumen!$B$8),FALSE())),MAX(IF(IFERROR(AND(W4<>"",Y4<>"",Y4-W4>Resumen!$B$8),FALSE()),Y4-W4,0),IF(IFERROR(AND(X4<>"",Y4<>"",Y4-X4>Resumen!$B$8),FALSE()),Y4-X4,0)),"") | AY4: =IF(OR(IFERROR(AND(W4<>"",Y4<>"",Y4-W4>Resumen!$B$8),FALSE()),IFERROR(AND(X4<>"",Y4<>"",Y4-X4>Resumen!$B$8),FALSE())),TRIM("Lays tiene mayor markup que "&IF(IFERROR(AND(W4<>"",Y4<>"",Y4-W4>Resumen!$B$8),FALSE()),"Quento ","")&IF(IFERROR(AND(X4<>"",Y4<>"",Y4-X4>Resumen!$B$8),FALSE()),"Julicroc ","")&"en este PDV"),"") | AZ4: =IF(COUNTIF('Plan Pehuamar - Lista'!$A$2:$A$167,A4)>0,"Sí","No") -> No | BA4: =IF(COUNTIF('Plan Combo 9+1'!$A$2:$A$226,A4)>0,"Sí","No") -> No | BB4: =IF(AH4="","No",IF(BA4="Sí",IF((AO4-AH4)>Resumen!$B$6,"Sí","No"),IF((AO4-AH4)>=Resumen!$B$132,"Sí","No"))) -> No | BC4: =IF(AND(N4="Sí",AL4="Sí",AI4=0),"Sí","No") -> No | BD4: =IF(COUNTIF('Plan 9+1 (con Pehuamar)'!$A$2:$A$227,A4)>0,"Sí","No") -> Sí
A5: 400758 | B5: 1 | C5: 101 | D5: Lunes | E5: CLAUSEN DANIEL | F5: Kiosco/Maxikiosco | G5: Santa Fe | H5: Conrado Pujol | I5: 0 | J5: 0 | K5: 0.2 | L5: =I5+J5 -> 0 | M5: =L5+K5 -> 0.2 | N5: =IF(I5>0,"Sí","No") -> No | O5: =IF(J5>0,"Sí","No") -> No | P5: =IF(K5>0,"Sí","No") -> Sí | Q5: =IF(OR(I5>0,J5>0),"Sí","No") -> No | W5: =IF(AND(I5>0,R5>0),(S5-R5)/R5,"") | X5: =IF(AND(J5>0,T5>0),(U5-T5)/T5,"") | Y5: =IF(AND(K5>0,V5>0),(V5-Resumen!$B$7)/Resumen!$B$7,"") | Z5: =IF(AND(K5>0,I5>0,V5>0,S5>0),V5-S5,"") | AA5: =IF(Z5<>"",Z5/S5,"") | AB5: =IF(AND(K5>0,J5>0,V5>0,U5>0),V5-U5,"") | AC5: =IF(AB5<>"",AB5/U5,"") | AD5: 0 | AE5: 0 | AF5: 0 | AG5: =AD5+AE5+AF5 -> 0 | AH5: =IF(AG5>0,AD5/AG5,"") | AI5: 0 | AJ5: 0 | AK5: 0 | AL5: =IF(OR(AJ5>0,AK5>0),"Sí","No") -> No | AO5: =IF(M5>0,K5/M5,"") -> 1 | AP5: =IF(M5>=Resumen!$B$5,"Alto","Bajo") -> Bajo | AQ5: =IF(AO5>=Resumen!$B$28,"Alto","Bajo") -> Alto | AR5: =AP5&" Potencial / "&AQ5&" Share" -> Bajo Potencial / Alto Share | AS5: =IF(Q5="Sí",IF(AO5>=Resumen!$B$29,"Alto","Bajo"),"") | AT5: =IF(AS5<>"",AP5&" Potencial / "&AS5&" Share","") | AU5: =IF(AH5="","Sin dato",IF(AH5-AO5>Resumen!$B$6,"Sobre-exhibido",IF(AO5-AH5>Resumen!$B$6,"Sub-exhibido","En línea"))) -> Sin dato | AV5: =IF(AT5="","",IF(AT5="Alto Potencial / Bajo Share",1,IF(AT5="Alto Potencial / Alto Share",2,IF(AT5="Bajo Potencial / Alto Share",3,4)))) | AW5: =IF(Q5="No","Sin competencia directa",IF(AV5=1,"1 - Foco Conquista (Alto Pot / Bajo Share)",IF(AV5=2,"2 - Foco Defensa (Alto Pot / Alto Share)",IF(AV5=3,"3 - Monitoreo (Bajo Pot / Alto Share)","4 - Baja Prioridad (Bajo Pot / Bajo Share)")))) -> Sin competencia directa | AX5: =IF(OR(IFERROR(AND(W5<>"",Y5<>"",Y5-W5>Resumen!$B$8),FALSE()),IFERROR(AND(X5<>"",Y5<>"",Y5-X5>Resumen!$B$8),FALSE())),MAX(IF(IFERROR(AND(W5<>"",Y5<>"",Y5-W5>Resumen!$B$8),FALSE()),Y5-W5,0),IF(IFERROR(AND(X5<>"",Y5<>"",Y5-X5>Resumen!$B$8),FALSE()),Y5-X5,0)),"") | AY5: =IF(OR(IFERROR(AND(W5<>"",Y5<>"",Y5-W5>Resumen!$B$8),FALSE()),IFERROR(AND(X5<>"",Y5<>"",Y5-X5>Resumen!$B$8),FALSE())),TRIM("Lays tiene mayor markup que "&IF(IFERROR(AND(W5<>"",Y5<>"",Y5-W5>Resumen!$B$8),FALSE()),"Quento ","")&IF(IFERROR(AND(X5<>"",Y5<>"",Y5-X5>Resumen!$B$8),FALSE()),"Julicroc ","")&"en este PDV"),"") | AZ5: =IF(COUNTIF('Plan Pehuamar - Lista'!$A$2:$A$167,A5)>0,"Sí","No") -> No | BA5: =IF(COUNTIF('Plan Combo 9+1'!$A$2:$A$226,A5)>0,"Sí","No") -> No | BB5: =IF(AH5="","No",IF(BA5="Sí",IF((AO5-AH5)>Resumen!$B$6,"Sí","No"),IF((AO5-AH5)>=Resumen!$B$132,"Sí","No"))) -> No | BC5: =IF(AND(N5="Sí",AL5="Sí",AI5=0),"Sí","No") -> No | BD5: =IF(COUNTIF('Plan 9+1 (con Pehuamar)'!$A$2:$A$227,A5)>0,"Sí","No") -> No
A6: 400761 | B6: 1 | C6: 101 | D6: Lunes | E6: SANCHEZ MARIA JOSE | F6: Almacen/Despensa | G6: Santa Fe | H6: Conrado Pujol | I6: 0 | J6: 0 | K6: 0.4 | L6: =I6+J6 -> 0 | M6: =L6+K6 -> 0.4 | N6: =IF(I6>0,"Sí","No") -> No | O6: =IF(J6>0,"Sí","No") -> No | P6: =IF(K6>0,"Sí","No") -> Sí | Q6: =IF(OR(I6>0,J6>0),"Sí","No") -> No | W6: =IF(AND(I6>0,R6>0),(S6-R6)/R6,"") | X6: =IF(AND(J6>0,T6>0),(U6-T6)/T6,"") | Y6: =IF(AND(K6>0,V6>0),(V6-Resumen!$B$7)/Resumen!$B$7,"") | Z6: =IF(AND(K6>0,I6>0,V6>0,S6>0),V6-S6,"") | AA6: =IF(Z6<>"",Z6/S6,"") | AB6: =IF(AND(K6>0,J6>0,V6>0,U6>0),V6-U6,"") | AC6: =IF(AB6<>"",AB6/U6,"") | AD6: 0 | AE6: 0 | AF6: 0 | AG6: =AD6+AE6+AF6 -> 0 | AH6: =IF(AG6>0,AD6/AG6,"") | AI6: 0 | AJ6: 0 | AK6: 0 | AL6: =IF(OR(AJ6>0,AK6>0),"Sí","No") -> No | AO6: =IF(M6>0,K6/M6,"") -> 1 | AP6: =IF(M6>=Resumen!$B$5,"Alto","Bajo") -> Bajo | AQ6: =IF(AO6>=Resumen!$B$28,"Alto","Bajo") -> Alto | AR6: =AP6&" Potencial / "&AQ6&" Share" -> Bajo Potencial / Alto Share | AS6: =IF(Q6="Sí",IF(AO6>=Resumen!$B$29,"Alto","Bajo"),"") | AT6: =IF(AS6<>"",AP6&" Potencial / "&AS6&" Share","") | AU6: =IF(AH6="","Sin dato",IF(AH6-AO6>Resumen!$B$6,"Sobre-exhibido",IF(AO6-AH6>Resumen!$B$6,"Sub-exhibido","En línea"))) -> Sin dato | AV6: =IF(AT6="","",IF(AT6="Alto Potencial / Bajo Share",1,IF(AT6="Alto Potencial / Alto Share",2,IF(AT6="Bajo Potencial / Alto Share",3,4)))) | AW6: =IF(Q6="No","Sin competencia directa",IF(AV6=1,"1 - Foco Conquista (Alto Pot / Bajo Share)",IF(AV6=2,"2 - Foco Defensa (Alto Pot / Alto Share)",IF(AV6=3,"3 - Monitoreo (Bajo Pot / Alto Share)","4 - Baja Prioridad (Bajo Pot / Bajo Share)")))) -> Sin competencia directa | AX6: =IF(OR(IFERROR(AND(W6<>"",Y6<>"",Y6-W6>Resumen!$B$8),FALSE()),IFERROR(AND(X6<>"",Y6<>"",Y6-X6>Resumen!$B$8),FALSE())),MAX(IF(IFERROR(AND(W6<>"",Y6<>"",Y6-W6>Resumen!$B$8),FALSE()),Y6-W6,0),IF(IFERROR(AND(X6<>"",Y6<>"",Y6-X6>Resumen!$B$8),FALSE()),Y6-X6,0)),"") | AY6: =IF(OR(IFERROR(AND(W6<>"",Y6<>"",Y6-W6>Resumen!$B$8),FALSE()),IFERROR(AND(X6<>"",Y6<>"",Y6-X6>Resumen!$B$8),FALSE())),TRIM("Lays tiene mayor markup que "&IF(IFERROR(AND(W6<>"",Y6<>"",Y6-W6>Resumen!$B$8),FALSE()),"Quento ","")&IF(IFERROR(AND(X6<>"",Y6<>"",Y6-X6>Resumen!$B$8),FALSE()),"Julicroc ","")&"en este PDV"),"") | AZ6: =IF(COUNTIF('Plan Pehuamar - Lista'!$A$2:$A$167,A6)>0,"Sí","No") -> No | BA6: =IF(COUNTIF('Plan Combo 9+1'!$A$2:$A$226,A6)>0,"Sí","No") -> No | BB6: =IF(AH6="","No",IF(BA6="Sí",IF((AO6-AH6)>Resumen!$B$6,"Sí","No"),IF((AO6-AH6)>=Resumen!$B$132,"Sí","No"))) -> No | BC6: =IF(AND(N6="Sí",AL6="Sí",AI6=0),"Sí","No") -> No | BD6: =IF(COUNTIF('Plan 9+1 (con Pehuamar)'!$A$2:$A$227,A6)>0,"Sí","No") -> No
A7: 400766 | B7: 1 | C7: 101 | D7: Lunes | E7: SULIGOY ALBERTO RAUL | F7: Almacen/Despensa | G7: Santa Fe | H7: Conrado Pujol | I7: 15 | J7: 20 | K7: 10 | L7: =I7+J7 -> 35 | M7: =L7+K7 -> 45 | N7: =IF(I7>0,"Sí","No") -> Sí | O7: =IF(J7>0,"Sí","No") -> Sí | P7: =IF(K7>0,"Sí","No") -> Sí | Q7: =IF(OR(I7>0,J7>0),"Sí","No") -> Sí | R7: 1900 | S7: 2700 | T7: 1600 | U7: 2400 | V7: 3500 | W7: =IF(AND(I7>0,R7>0),(S7-R7)/R7,"") -> 0.42105263 | X7: =IF(AND(J7>0,T7>0),(U7-T7)/T7,"") -> 0.5 | Y7: =IF(AND(K7>0,V7>0),(V7-Resumen!$B$7)/Resumen!$B$7,"") -> 0.4 | Z7: =IF(AND(K7>0,I7>0,V7>0,S7>0),V7-S7,"") -> 800 | AA7: =IF(Z7<>"",Z7/S7,"") -> 0.2962963 | AB7: =IF(AND(K7>0,J7>0,V7>0,U7>0),V7-U7,"") -> 1100 | AC7: =IF(AB7<>"",AB7/U7,"") -> 0.45833333 | AD7: 3 | AE7: 4 | AF7: 3 | AG7: =AD7+AE7+AF7 -> 10 | AH7: =IF(AG7>0,AD7/AG7,"") -> 0.3 | AI7: 0 | AJ7: 0 | AK7: 0 | AL7: =IF(OR(AJ7>0,AK7>0),"Sí","No") -> No | AM7: Contado | AN7: Contado | AO7: =IF(M7>0,K7/M7,"") -> 0.22222222 | AP7: =IF(M7>=Resumen!$B$5,"Alto","Bajo") -> Alto | AQ7: =IF(AO7>=Resumen!$B$28,"Alto","Bajo") -> Bajo | AR7: =AP7&" Potencial / "&AQ7&" Share" -> Alto Potencial / Bajo Share | AS7: =IF(Q7="Sí",IF(AO7>=Resumen!$B$29,"Alto","Bajo"),"") -> Bajo | AT7: =IF(AS7<>"",AP7&" Potencial / "&AS7&" Share","") -> Alto Potencial / Bajo Share | AU7: =IF(AH7="","Sin dato",IF(AH7-AO7>Resumen!$B$6,"Sobre-exhibido",IF(AO7-AH7>Resumen!$B$6,"Sub-exhibido","En línea"))) -> Sobre-exhibido | AV7: =IF(AT7="","",IF(AT7="Alto Potencial / Bajo Share",1,IF(AT7="Alto Potencial / Alto Share",2,IF(AT7="Bajo Potencial / Alto Share",3,4)))) -> 1 | AW7: =IF(Q7="No","Sin competencia directa",IF(AV7=1,"1 - Foco Conquista (Alto Pot / Bajo Share)",IF(AV7=2,"2 - Foco Defensa (Alto Pot / Alto Share)",IF(AV7=3,"3 - Monitoreo (Bajo Pot / Alto Share)","4 - Baja Prioridad (Bajo Pot / Bajo Share)")))) -> 1 - Foco Conquista (Alto Pot / Bajo Share) | AX7: =IF(OR(IFERROR(AND(W7<>"",Y7<>"",Y7-W7>Resumen!$B$8),FALSE()),IFERROR(AND(X7<>"",Y7<>"",Y7-X7>Resumen!$B$8),FALSE())),MAX(IF(IFERROR(AND(W7<>"",Y7<>"",Y7-W7>Resumen!$B$8),FALSE()),Y7-W7,0),IF(IFERROR(AND(X7<>"",Y7<>"",Y7-X7>Resumen!$B$8),FALSE()),Y7-X7,0)),"") | AY7: =IF(OR(IFERROR(AND(W7<>"",Y7<>"",Y7-W7>Resumen!$B$8),FALSE()),IFERROR(AND(X7<>"",Y7<>"",Y7-X7>Resumen!$B$8),FALSE())),TRIM("Lays tiene mayor markup que "&IF(IFERROR(AND(W7<>"",Y7<>"",Y7-W7>Resumen!$B$8),FALSE()),"Quento ","")&IF(IFERROR(AND(X7<>"",Y7<>"",Y7-X7>Resumen!$B$8),FALSE()),"Julicroc ","")&"en este PDV"),"") | AZ7: =IF(COUNTIF('Plan Pehuamar - Lista'!$A$2:$A$167,A7)>0,"Sí","No") -> No | BA7: =IF(COUNTIF('Plan Combo 9+1'!$A$2:$A$226,A7)>0,"Sí","No") -> Sí | BB7: =IF(AH7="","No",IF(BA7="Sí",IF((AO7-AH7)>Resumen!$B$6,"Sí","No"),IF((AO7-AH7)>=Resumen!$B$132,"Sí","No"))) -> No | BC7: =IF(AND(N7="Sí",AL7="Sí",AI7=0),"Sí","No") -> No | BD7: =IF(COUNTIF('Plan 9+1 (con Pehuamar)'!$A$2:$A$227,A7)>0,"Sí","No") -> Sí
A8: 400770 | B8: 1 | C8: 101 | D8: Lunes | E8: BATTISTELLA MIGUEL ANGEL | F8: Autoservicio Tradicional | G8: Santa Fe | H8: Conrado Pujol | I8: 25 | J8: 20 | K8: 15 | L8: =I8+J8 -> 45 | M8: =L8+K8 -> 60 | N8: =IF(I8>0,"Sí","No") -> Sí | O8: =IF(J8>0,"Sí","No") -> Sí | P8: =IF(K8>0,"Sí","No") -> Sí | Q8: =IF(OR(I8>0,J8>0),"Sí","No") -> Sí | R8: 2000 | S8: 2900 | T8: 1800 | U8: 2500 | V8: 3700 | W8: =IF(AND(I8>0,R8>0),(S8-R8)/R8,"") -> 0.45 | X8: =IF(AND(J8>0,T8>0),(U8-T8)/T8,"") -> 0.38888889 | Y8: =IF(AND(K8>0,V8>0),(V8-Resumen!$B$7)/Resumen!$B$7,"") -> 0.48 | Z8: =IF(AND(K8>0,I8>0,V8>0,S8>0),V8-S8,"") -> 800 | AA8: =IF(Z8<>"",Z8/S8,"") -> 0.27586207 | AB8: =IF(AND(K8>0,J8>0,V8>0,U8>0),V8-U8,"") -> 1200 | AC8: =IF(AB8<>"",AB8/U8,"") -> 0.48 | AD8: 5 | AE8: 3 | AF8: 3 | AG8: =AD8+AE8+AF8 -> 11 | AH8: =IF(AG8>0,AD8/AG8,"") -> 0.45454545 | AI8: 1 | AJ8: 1 | AK8: 0 | AL8: =IF(OR(AJ8>0,AK8>0),"Sí","No") -> Sí | AM8: Contado | AN8: Contado | AO8: =IF(M8>0,K8/M8,"") -> 0.25 | AP8: =IF(M8>=Resumen!$B$5,"Alto","Bajo") -> Alto | AQ8: =IF(AO8>=Resumen!$B$28,"Alto","Bajo") -> Bajo | AR8: =AP8&" Potencial / "&AQ8&" Share" -> Alto Potencial / Bajo Share | AS8: =IF(Q8="Sí",IF(AO8>=Resumen!$B$29,"Alto","Bajo"),"") -> Bajo | AT8: =IF(AS8<>"",AP8&" Potencial / "&AS8&" Share","") -> Alto Potencial / Bajo Share | AU8: =IF(AH8="","Sin dato",IF(AH8-AO8>Resumen!$B$6,"Sobre-exhibido",IF(AO8-AH8>Resumen!$B$6,"Sub-exhibido","En línea"))) -> Sobre-exhibido | AV8: =IF(AT8="","",IF(AT8="Alto Potencial / Bajo Share",1,IF(AT8="Alto Potencial / Alto Share",2,IF(AT8="Bajo Potencial / Alto Share",3,4)))) -> 1 | AW8: =IF(Q8="No","Sin competencia directa",IF(AV8=1,"1 - Foco Conquista (Alto Pot / Bajo Share)",IF(AV8=2,"2 - Foco Defensa (Alto Pot / Alto Share)",IF(AV8=3,"3 - Monitoreo (Bajo Pot / Alto Share)","4 - Baja Prioridad (Bajo Pot / Bajo Share)")))) -> 1 - Foco Conquista (Alto Pot / Bajo Share) | AX8: =IF(OR(IFERROR(AND(W8<>"",Y8<>"",Y8-W8>Resumen!$B$8),FALSE()),IFERROR(AND(X8<>"",Y8<>"",Y8-X8>Resumen!$B$8),FALSE())),MAX(IF(IFERROR(AND(W8<>"",Y8<>"",Y8-W8>Resumen!$B$8),FALSE()),Y8-W8,0),IF(IFERROR(AND(X8<>"",Y8<>"",Y8-X8>Resumen!$B$8),FALSE()),Y8-X8,0)),"") -> 0.091111111 | AY8: =IF(OR(IFERROR(AND(W8<>"",Y8<>"",Y8-W8>Resumen!$B$8),FALSE()),IFERROR(AND(X8<>"",Y8<>"",Y8-X8>Resumen!$B$8),FALSE())),TRIM("Lays tiene mayor markup que "&IF(IFERROR(AND(W8<>"",Y8<>"",Y8-W8>Resumen!$B$8),FALSE()),"Quento ","")&IF(IFERROR(AND(X8<>"",Y8<>"",Y8-X8>Resumen!$B$8),FALSE()),"Julicroc ","")&"en este PDV"),"") -> Lays tiene mayor markup que Julicroc en este PDV | AZ8: =IF(COUNTIF('Plan Pehuamar - Lista'!$A$2:$A$167,A8)>0,"Sí","No") -> No | BA8: =IF(COUNTIF('Plan Combo 9+1'!$A$2:$A$226,A8)>0,"Sí","No") -> Sí | BB8: =IF(AH8="","No",IF(BA8="Sí",IF((AO8-AH8)>Resumen!$B$6,"Sí","No"),IF((AO8-AH8)>=Resumen!$B$132,"Sí","No"))) -> No | BC8: =IF(AND(N8="Sí",AL8="Sí",AI8=0),"Sí","No") -> No | BD8: =IF(COUNTIF('Plan 9+1 (con Pehuamar)'!$A$2:$A$227,A8)>0,"Sí","No") -> Sí
A9: 400771 | B9: 1 | C9: 101 | D9: Lunes | E9: PANIFICACION KOCH SRL | F9: Almacen/Despensa | G9: Santa Fe | H9: Conrado Pujol | I9: 0 | J9: 0 | K9: 0.4 | L9: =I9+J9 -> 0 | M9: =L9+K9 -> 0.4 | N9: =IF(I9>0,"Sí","No") -> No | O9: =IF(J9>0,"Sí","No") -> No | P9: =IF(K9>0,"Sí","No") -> Sí | Q9: =IF(OR(I9>0,J9>0),"Sí","No") -> No | W9: =IF(AND(I9>0,R9>0),(S9-R9)/R9,"") | X9: =IF(AND(J9>0,T9>0),(U9-T9)/T9,"") | Y9: =IF(AND(K9>0,V9>0),(V9-Resumen!$B$7)/Resumen!$B$7,"") | Z9: =IF(AND(K9>0,I9>0,V9>0,S9>0),V9-S9,"") | AA9: =IF(Z9<>"",Z9/S9,"") | AB9: =IF(AND(K9>0,J9>0,V9>0,U9>0),V9-U9,"") | AC9: =IF(AB9<>"",AB9/U9,"") | AD9: 0 | AE9: 0 | AF9: 0 | AG9: =AD9+AE9+AF9 -> 0 | AH9: =IF(AG9>0,AD9/AG9,"") | AI9: 0 | AJ9: 0 | AK9: 0 | AL9: =IF(OR(AJ9>0,AK9>0),"Sí","No") -> No | AO9: =IF(M9>0,K9/M9,"") -> 1 | AP9: =IF(M9>=Resumen!$B$5,"Alto","Bajo") -> Bajo | AQ9: =IF(AO9>=Resumen!$B$28,"Alto","Bajo") -> Alto | AR9: =AP9&" Potencial / "&AQ9&" Share" -> Bajo Potencial / Alto Share | AS9: =IF(Q9="Sí",IF(AO9>=Resumen!$B$29,"Alto","Bajo"),"") | AT9: =IF(AS9<>"",AP9&" Potencial / "&AS9&" Share","") | AU9: =IF(AH9="","Sin dato",IF(AH9-AO9>Resumen!$B$6,"Sobre-exhibido",IF(AO9-AH9>Resumen!$B$6,"Sub-exhibido","En línea"))) -> Sin dato | AV9: =IF(AT9="","",IF(AT9="Alto Potencial / Bajo Share",1,IF(AT9="Alto Potencial / Alto Share",2,IF(AT9="Bajo Potencial / Alto Share",3,4)))) | AW9: =IF(Q9="No","Sin competencia directa",IF(AV9=1,"1 - Foco Conquista (Alto Pot / Bajo Share)",IF(AV9=2,"2 - Foco Defensa (Alto Pot / Alto Share)",IF(AV9=3,"3 - Monitoreo (Bajo Pot / Alto Share)","4 - Baja Prioridad (Bajo Pot / Bajo Share)")))) -> Sin competencia directa | AX9: =IF(OR(IFERROR(AND(W9<>"",Y9<>"",Y9-W9>Resumen!$B$8),FALSE()),IFERROR(AND(X9<>"",Y9<>"",Y9-X9>Resumen!$B$8),FALSE())),MAX(IF(IFERROR(AND(W9<>"",Y9<>"",Y9-W9>Resumen!$B$8),FALSE()),Y9-W9,0),IF(IFERROR(AND(X9<>"",Y9<>"",Y9-X9>Resumen!$B$8),FALSE()),Y9-X9,0)),"") | AY9: =IF(OR(IFERROR(AND(W9<>"",Y9<>"",Y9-W9>Resumen!$B$8),FALSE()),IFERROR(AND(X9<>"",Y9<>"",Y9-X9>Resumen!$B$8),FALSE())),TRIM("Lays tiene mayor markup que "&IF(IFERROR(AND(W9<>"",Y9<>"",Y9-W9>Resumen!$B$8),FALSE()),"Quento ","")&IF(IFERROR(AND(X9<>"",Y9<>"",Y9-X9>Resumen!$B$8),FALSE()),"Julicroc ","")&"en este PDV"),"") | AZ9: =IF(COUNTIF('Plan Pehuamar - Lista'!$A$2:$A$167,A9)>0,"Sí","No") -> No | BA9: =IF(COUNTIF('Plan Combo 9+1'!$A$2:$A$226,A9)>0,"Sí","No") -> No | BB9: =IF(AH9="","No",IF(BA9="Sí",IF((AO9-AH9)>Resumen!$B$6,"Sí","No"),IF((AO9-AH9)>=Resumen!$B$132,"Sí","No"))) -> No | BC9: =IF(AND(N9="Sí",AL9="Sí",AI9=0),"Sí","No") -> No | BD9: =IF(COUNTIF('Plan 9+1 (con Pehuamar)'!$A$2:$A$227,A9)>0,"Sí","No") -> No
A10: 400789 | B10: 1 | C10: 101 | D10: Lunes | E10: VALIENTE HECTOR DARIO | F10: Almacen/Despensa | G10: Santa Fe | H10: Conrado Pujol | I10: 0 | J10: 0 | K10: 0.9 | L10: =I10+J10 -> 0 | M10: =L10+K10 -> 0.9 | N10: =IF(I10>0,"Sí","No") -> No | O10: =IF(J10>0,"Sí","No") -> No | P10: =IF(K10>0,"Sí","No") -> Sí | Q10: =IF(OR(I10>0,J10>0),"Sí","No") -> No | W10: =IF(AND(I10>0,R10>0),(S10-R10)/R10,"") | X10: =IF(AND(J10>0,T10>0),(U10-T10)/T10,"") | Y10: =IF(AND(K10>0,V10>0),(V10-Resumen!$B$7)/Resumen!$B$7,"") | Z10: =IF(AND(K10>0,I10>0,V10>0,S10>0),V10-S10,"") | AA10: =IF(Z10<>"",Z10/S10,"") | AB10: =IF(AND(K10>0,J10>0,V10>0,U10>0),V10-U10,"") | AC10: =IF(AB10<>"",AB10/U10,"") | AD10: 0 | AE10: 0 | AF10: 0 | AG10: =AD10+AE10+AF10 -> 0 | AH10: =IF(AG10>0,AD10/AG10,"") | AI10: 0 | AJ10: 0 | AK10: 0 | AL10: =IF(OR(AJ10>0,AK10>0),"Sí","No") -> No | AO10: =IF(M10>0,K10/M10,"") -> 1 | AP10: =IF(M10>=Resumen!$B$5,"Alto","Bajo") -> Bajo | AQ10: =IF(AO10>=Resumen!$B$28,"Alto","Bajo") -> Alto | AR10: =AP10&" Potencial / "&AQ10&" Share" -> Bajo Potencial / Alto Share | AS10: =IF(Q10="Sí",IF(AO10>=Resumen!$B$29,"Alto","Bajo"),"") | AT10: =IF(AS10<>"",AP10&" Potencial / "&AS10&" Share","") | AU10: =IF(AH10="","Sin dato",IF(AH10-AO10>Resumen!$B$6,"Sobre-exhibido",IF(AO10-AH10>Resumen!$B$6,"Sub-exhibido","En línea"))) -> Sin dato | AV10: =IF(AT10="","",IF(AT10="Alto Potencial / Bajo Share",1,IF(AT10="Alto Potencial / Alto Share",2,IF(AT10="Bajo Potencial / Alto Share",3,4)))) | AW10: =IF(Q10="No","Sin competencia directa",IF(AV10=1,"1 - Foco Conquista (Alto Pot / Bajo Share)",IF(AV10=2,"2 - Foco Defensa (Alto Pot / Alto Share)",IF(AV10=3,"3 - Monitoreo (Bajo Pot / Alto Share)","4 - Baja Prioridad (Bajo Pot / Bajo Share)")))) -> Sin competencia directa | AX10: =IF(OR(IFERROR(AND(W10<>"",Y10<>"",Y10-W10>Resumen!$B$8),FALSE()),IFERROR(AND(X10<>"",Y10<>"",Y10-X10>Resumen!$B$8),FALSE())),MAX(IF(IFERROR(AND(W10<>"",Y10<>"",Y10-W10>Resumen!$B$8),FALSE()),Y10-W10,0),IF(IFERROR(AND(X10<>"",Y10<>"",Y10-X10>Resumen!$B$8),FALSE()),Y10-X10,0)),"") | AY10: =IF(OR(IFERROR(AND(W10<>"",Y10<>"",Y10-W10>Resumen!$B$8),FALSE()),IFERROR(AND(X10<>"",Y10<>"",Y10-X10>Resumen!$B$8),FALSE())),TRIM("Lays tiene mayor markup que "&IF(IFERROR(AND(W10<>"",Y10<>"",Y10-W10>Resumen!$B$8),FALSE()),"Quento ","")&IF(IFERROR(AND(X10<>"",Y10<>"",Y10-X10>Resumen!$B$8),FALSE()),"Julicroc ","")&"en este PDV"),"") | AZ10: =IF(COUNTIF('Plan Pehuamar - Lista'!$A$2:$A$167,A10)>0,"Sí","No") -> No | BA10: =IF(COUNTIF('Plan Combo 9+1'!$A$2:$A$226,A10)>0,"Sí","No") -> No | BB10: =IF(AH10="","No",IF(BA10="Sí",IF((AO10-AH10)>Resumen!$B$6,"Sí","No"),IF((AO10-AH10)>=Resumen!$B$132,"Sí","No"))) -> No | BC10: =IF(AND(N10="Sí",AL10="Sí",AI10=0),"Sí","No") -> No | BD10: =IF(COUNTIF('Plan 9+1 (con Pehuamar)'!$A$2:$A$227,A10)>0,"Sí","No") -> No
A11: 400790 | B11: 1 | C11: 101 | D11: Lunes | E11: GALIANO MARIANA ANALIA | F11: Panaderia | G11: Santa Fe | H11: Conrado Pujol | I11: 0 | J11: 0 | K11: 0.8 | L11: =I11+J11 -> 0 | M11: =L11+K11 -> 0.8 | N11: =IF(I11>0,"Sí","No") -> No | O11: =IF(J11>0,"Sí","No") -> No | P11: =IF(K11>0,"Sí","No") -> Sí | Q11: =IF(OR(I11>0,J11>0),"Sí","No") -> No | W11: =IF(AND(I11>0,R11>0),(S11-R11)/R11,"") | X11: =IF(AND(J11>0,T11>0),(U11-T11)/T11,"") | Y11: =IF(AND(K11>0,V11>0),(V11-Resumen!$B$7)/Resumen!$B$7,"") | Z11: =IF(AND(K11>0,I11>0,V11>0,S11>0),V11-S11,"") | AA11: =IF(Z11<>"",Z11/S11,"") | AB11: =IF(AND(K11>0,J11>0,V11>0,U11>0),V11-U11,"") | AC11: =IF(AB11<>"",AB11/U11,"") | AD11: 0 | AE11: 0 | AF11: 0 | AG11: =AD11+AE11+AF11 -> 0 | AH11: =IF(AG11>0,AD11/AG11,"") | AI11: 0 | AJ11: 0 | AK11: 0 | AL11: =IF(OR(AJ11>0,AK11>0),"Sí","No") -> No | AO11: =IF(M11>0,K11/M11,"") -> 1 | AP11: =IF(M11>=Resumen!$B$5,"Alto","Bajo") -> Bajo | AQ11: =IF(AO11>=Resumen!$B$28,"Alto","Bajo") -> Alto | AR11: =AP11&" Potencial / "&AQ11&" Share" -> Bajo Potencial / Alto Share | AS11: =IF(Q11="Sí",IF(AO11>=Resumen!$B$29,"Alto","Bajo"),"") | AT11: =IF(AS11<>"",AP11&" Potencial / "&AS11&" Share","") | AU11: =IF(AH11="","Sin dato",IF(AH11-AO11>Resumen!$B$6,"Sobre-exhibido",IF(AO11-AH11>Resumen!$B$6,"Sub-exhibido","En línea"))) -> Sin dato | AV11: =IF(AT11="","",IF(AT11="Alto Potencial / Bajo Share",1,IF(AT11="Alto Potencial / Alto Share",2,IF(AT11="Bajo Potencial / Alto Share",3,4)))) | AW11: =IF(Q11="No","Sin competencia directa",IF(AV11=1,"1 - Foco Conquista (Alto Pot / Bajo Share)",IF(AV11=2,"2 - Foco Defensa (Alto Pot / Alto Share)",IF(AV11=3,"3 - Monitoreo (Bajo Pot / Alto Share)","4 - Baja Prioridad (Bajo Pot / Bajo Share)")))) -> Sin competencia directa | AX11: =IF(OR(IFERROR(AND(W11<>"",Y11<>"",Y11-W11>Resumen!$B$8),FALSE()),IFERROR(AND(X11<>"",Y11<>"",Y11-X11>Resumen!$B$8),FALSE())),MAX(IF(IFERROR(AND(W11<>"",Y11<>"",Y11-W11>Resumen!$B$8),FALSE()),Y11-W11,0),IF(IFERROR(AND(X11<>"",Y11<>"",Y11-X11>Resumen!$B$8),FALSE()),Y11-X11,0)),"") | AY11: =IF(OR(IFERROR(AND(W11<>"",Y11<>"",Y11-W11>Resumen!$B$8),FALSE()),IFERROR(AND(X11<>"",Y11<>"",Y11-X11>Resumen!$B$8),FALSE())),TRIM("Lays tiene mayor markup que "&IF(IFERROR(AND(W11<>"",Y11<>"",Y11-W11>Resumen!$B$8),FALSE()),"Quento ","")&IF(IFERROR(AND(X11<>"",Y11<>"",Y11-X11>Resumen!$B$8),FALSE()),"Julicroc ","")&"en este PDV"),"") | AZ11: =IF(COUNTIF('Plan Pehuamar - Lista'!$A$2:$A$167,A11)>0,"Sí","No") -> No | BA11: =IF(COUNTIF('Plan Combo 9+1'!$A$2:$A$226,A11)>0,"Sí","No") -> No | BB11: =IF(AH11="","No",IF(BA11="Sí",IF((AO11-AH11)>Resumen!$B$6,"Sí","No"),IF((AO11-AH11)>=Resumen!$B$132,"Sí","No"))) -> No | BC11: =IF(AND(N11="Sí",AL11="Sí",AI11=0),"Sí","No") -> No | BD11: =IF(COUNTIF('Plan 9+1 (con Pehuamar)'!$A$2:$A$227,A11)>0,"Sí","No") -> No
A12: 400791 | B12: 1 | C12: 101 | D12: Lunes | E12: ARBIZU VIVIANA BELKYS | F12: Almacen/Despensa | G12: Santa Fe | H12: Conrado Pujol | I12: 15 | J12: 10 | K12: 15 | L12: =I12+J12 -> 25 | M12: =L12+K12 -> 40 | N12: =IF(I12>0,"Sí","No") -> Sí | O12: =IF(J12>0,"Sí","No") -> Sí | P12: =IF(K12>0,"Sí","No") -> Sí | Q12: =IF(OR(I12>0,J12>0),"Sí","No") -> Sí | R12: 1800 | S12: 3000 | T12: 1500 | U12: 2300 | V12: 3600 | W12: =IF(AND(I12>0,R12>0),(S12-R12)/R12,"") -> 0.66666667 | X12: =IF(AND(J12>0,T12>0),(U12-T12)/T12,"") -> 0.53333333 | Y12: =IF(AND(K12>0,V12>0),(V12-Resumen!$B$7)/Resumen!$B$7,"") -> 0.44 | Z12: =IF(AND(K12>0,I12>0,V12>0,S12>0),V12-S12,"") -> 600 | AA12: =IF(Z12<>"",Z12/S12,"") -> 0.2 | AB12: =IF(AND(K12>0,J12>0,V12>0,U12>0),V12-U12,"") -> 1300 | AC12: =IF(AB12<>"",AB12/U12,"") -> 0.56521739 | AD12: 3 | AE12: 3 | AF12: 2 | AG12: =AD12+AE12+AF12 -> 8 | AH12: =IF(AG12>0,AD12/AG12,"") -> 0.375 | AI12: 0 | AJ12: 0 | AK12: 0 | AL12: =IF(OR(AJ12>0,AK12>0),"Sí","No") -> No | AM12: Contado | AN12: Contado | AO12: =IF(M12>0,K12/M12,"") -> 0.375 | AP12: =IF(M12>=Resumen!$B$5,"Alto","Bajo") -> Alto | AQ12: =IF(AO12>=Resumen!$B$28,"Alto","Bajo") -> Bajo | AR12: =AP12&" Potencial / "&AQ12&" Share" -> Alto Potencial / Bajo Share | AS12: =IF(Q12="Sí",IF(AO12>=Resumen!$B$29,"Alto","Bajo"),"") -> Bajo | AT12: =IF(AS12<>"",AP12&" Potencial / "&AS12&" Share","") -> Alto Potencial / Bajo Share | AU12: =IF(AH12="","Sin dato",IF(AH12-AO12>Resumen!$B$6,"Sobre-exhibido",IF(AO12-AH12>Resumen!$B$6,"Sub-exhibido","En línea"))) -> En línea | AV12: =IF(AT12="","",IF(AT12="Alto Potencial / Bajo Share",1,IF(AT12="Alto Potencial / Alto Share",2,IF(AT12="Bajo Potencial / Alto Share",3,4)))) -> 1 | AW12: =IF(Q12="No","Sin competencia directa",IF(AV12=1,"1 - Foco Conquista (Alto Pot / Bajo Share)",IF(AV12=2,"2 - Foco Defensa (Alto Pot / Alto Share)",IF(AV12=3,"3 - Monitoreo (Bajo Pot / Alto Share)","4 - Baja Prioridad (Bajo Pot / Bajo Share)")))) -> 1 - Foco Conquista (Alto Pot / Bajo Share) | AX12: =IF(OR(IFERROR(AND(W12<>"",Y12<>"",Y12-W12>Resumen!$B$8),FALSE()),IFERROR(AND(X12<>"",Y12<>"",Y12-X12>Resumen!$B$8),FALSE())),MAX(IF(IFERROR(AND(W12<>"",Y12<>"",Y12-W12>Resumen!$B$8),FALSE()),Y12-W12,0),IF(IFERROR(AND(X12<>"",Y12<>"",Y12-X12>Resumen!$B$8),FALSE()),Y12-X12,0)),"") | AY12: =IF(OR(IFERROR(AND(W12<>"",Y12<>"",Y12-W12>Resumen!$B$8),FALSE()),IFERROR(AND(X12<>"",Y12<>"",Y12-X12>Resumen!$B$8),FALSE())),TRIM("Lays tiene mayor markup que "&IF(IFERROR(AND(W12<>"",Y12<>"",Y12-W12>Resumen!$B$8),FALSE()),"Quento ","")&IF(IFERROR(AND(X12<>"",Y12<>"",Y12-X12>Resumen!$B$8),FALSE()),"Julicroc ","")&"en este PDV"),"") | AZ12: =IF(COUNTIF('Plan Pehuamar - Lista'!$A$2:$A$167,A12)>0,"Sí","No") -> No | BA12: =IF(COUNTIF('Plan Combo 9+1'!$A$2:$A$226,A12)>0,"Sí","No") -> No | BB12: =IF(AH12="","No",IF(BA12="Sí",IF((AO12-AH12)>Resumen!$B$6,"Sí","No"),IF((AO12-AH12)>=Resumen!$B$132,"Sí","No"))) -> No | BC12: =IF(AND(N12="Sí",AL12="Sí",AI12=0),"Sí","No") -> No | BD12: =IF(COUNTIF('Plan 9+1 (con Pehuamar)'!$A$2:$A$227,A12)>0,"Sí","No") -> No
A13: 400976 | B13: 1 | C13: 101 | D13: Lunes | E13: CABRERA MARIA CRISTINA | F13: Rotiseria | G13: Santa Fe | H13: Conrado Pujol | I13: 20 | J13: 15 | K13: 15 | L13: =I13+J13 -> 35 | M13: =L13+K13 -> 50 | N13: =IF(I13>0,"Sí","No") -> Sí | O13: =IF(J13>0,"Sí","No") -> Sí | P13: =IF(K13>0,"Sí","No") -> Sí | Q13: =IF(OR(I13>0,J13>0),"Sí","No") -> Sí | R13: 1800 | S13: 2800 | T13: 1600 | U13: 2500 | V13: 3700 | W13: =IF(AND(I13>0,R13>0),(S13-R13)/R13,"") -> 0.55555556 | X13: =IF(AND(J13>0,T13>0),(U13-T13)/T13,"") -> 0.5625 | Y13: =IF(AND(K13>0,V13>0),(V13-Resumen!$B$7)/Resumen!$B$7,"") -> 0.48 | Z13: =IF(AND(K13>0,I13>0,V13>0,S13>0),V13-S13,"") -> 900 | AA13: =IF(Z13<>"",Z13/S13,"") -> 0.32142857 | AB13: =IF(AND(K13>0,J13>0,V13>0,U13>0),V13-U13,"") -> 1200 | AC13: =IF(AB13<>"",AB13/U13,"") -> 0.48 | AD13: 4 | AE13: 3 | AF13: 3 | AG13: =AD13+AE13+AF13 -> 10 | AH13: =IF(AG13>0,AD13/AG13,"") -> 0.4 | AI13: 0 | AJ13: 0 | AK13: 0 | AL13: =IF(OR(AJ13>0,AK13>0),"Sí","No") -> No | AM13: Contado | AN13: Contado | AO13: =IF(M13>0,K13/M13,"") -> 0.3 | AP13: =IF(M13>=Resumen!$B$5,"Alto","Bajo") -> Alto | AQ13: =IF(AO13>=Resumen!$B$28,"Alto","Bajo") -> Bajo | AR13: =AP13&" Potencial / "&AQ13&" Share" -> Alto Potencial / Bajo Share | AS13: =IF(Q13="Sí",IF(AO13>=Resumen!$B$29,"Alto","Bajo"),"") -> Bajo | AT13: =IF(AS13<>"",AP13&" Potencial / "&AS13&" Share","") -> Alto Potencial / Bajo Share | AU13: =IF(AH13="","Sin dato",IF(AH13-AO13>Resumen!$B$6,"Sobre-exhibido",IF(AO13-AH13>Resumen!$B$6,"Sub-exhibido","En línea"))) -> Sobre-exhibido | AV13: =IF(AT13="","",IF(AT13="Alto Potencial / Bajo Share",1,IF(AT13="Alto Potencial / Alto Share",2,IF(AT13="Bajo Potencial / Alto Share",3,4)))) -> 1 | AW13: =IF(Q13="No","Sin competencia directa",IF(AV13=1,"1 - Foco Conquista (Alto Pot / Bajo Share)",IF(AV13=2,"2 - Foco Defensa (Alto Pot / Alto Share)",IF(AV13=3,"3 - Monitoreo (Bajo Pot / Alto Share)","4 - Baja Prioridad (Bajo Pot / Bajo Share)")))) -> 1 - Foco Conquista (Alto Pot / Bajo Share) | AX13: =IF(OR(IFERROR(AND(W13<>"",Y13<>"",Y13-W13>Resumen!$B$8),FALSE()),IFERROR(AND(X13<>"",Y13<>"",Y13-X13>Resumen!$B$8),FALSE())),MAX(IF(IFERROR(AND(W13<>"",Y13<>"",Y13-W13>Resumen!$B$8),FALSE()),Y13-W13,0),IF(IFERROR(AND(X13<>"",Y13<>"",Y13-X13>Resumen!$B$8),FALSE()),Y13-X13,0)),"") | AY13: =IF(OR(IFERROR(AND(W13<>"",Y13<>"",Y13-W13>Resumen!$B$8),FALSE()),IFERROR(AND(X13<>"",Y13<>"",Y13-X13>Resumen!$B$8),FALSE())),TRIM("Lays tiene mayor markup que "&IF(IFERROR(AND(W13<>"",Y13<>"",Y13-W13>Resumen!$B$8),FALSE()),"Quento ","")&IF(IFERROR(AND(X13<>"",Y13<>"",Y13-X13>Resumen!$B$8),FALSE()),"Julicroc ","")&"en este PDV"),"") | AZ13: =IF(COUNTIF('Plan Pehuamar - Lista'!$A$2:$A$167,A13)>0,"Sí","No") -> No | BA13: =IF(COUNTIF('Plan Combo 9+1'!$A$2:$A$226,A13)>0,"Sí","No") -> Sí | BB13: =IF(AH13="","No",IF(BA13="Sí",IF((AO13-AH13)>Resumen!$B$6,"Sí","No"),IF((AO13-AH13)>=Resumen!$B$132,"Sí","No"))) -> No | BC13: =IF(AND(N13="Sí",AL13="Sí",AI13=0),"Sí","No") -> No | BD13: =IF(COUNTIF('Plan 9+1 (con Pehuamar)'!$A$2:$A$227,A13)>0,"Sí","No") -> Sí
A14: 400995 | B14: 1 | C14: 101 | D14: Lunes | E14: MAINA GUSTAVO JOSE | F14: Almacen/Despensa | G14: Santa Fe | H14: Conrado Pujol | I14: 40 | J14: 20 | K14: 30 | L14: =I14+J14 -> 60 | M14: =L14+K14 -> 90 | N14: =IF(I14>0,"Sí","No") -> Sí | O14: =IF(J14>0,"Sí","No") -> Sí | P14: =IF(K14>0,"Sí","No") -> Sí | Q14: =IF(OR(I14>0,J14>0),"Sí","No") -> Sí | R14: 1900 | S14: 2700 | T14: 1800 | U14: 2400 | V14: 3600 | W14: =IF(AND(I14>0,R14>0),(S14-R14)/R14,"") -> 0.42105263 | X14: =IF(AND(J14>0,T14>0),(U14-T14)/T14,"") -> 0.33333333 | Y14: =IF(AND(K14>0,V14>0),(V14-Resumen!$B$7)/Resumen!$B$7,"") -> 0.44 | Z14: =IF(AND(K14>0,I14>0,V14>0,S14>0),V14-S14,"") -> 900 | AA14: =IF(Z14<>"",Z14/S14,"") -> 0.33333333 | AB14: =IF(AND(K14>0,J14>0,V14>0,U14>0),V14-U14,"") -> 1200 | AC14: =IF(AB14<>"",AB14/U14,"") -> 0.5 | AD14: 6 | AE14: 5 | AF14: 4 | AG14: =AD14+AE14+AF14 -> 15 | AH14: =IF(AG14>0,AD14/AG14,"") -> 0.4 | AI14: 0 | AJ14: 0 | AK14: 0 | AL14: =IF(OR(AJ14>0,AK14>0),"Sí","No") -> No | AM14: Contado | AN14: Contado | AO14: =IF(M14>0,K14/M14,"") -> 0.33333333 | AP14: =IF(M14>=Resumen!$B$5,"Alto","Bajo") -> Alto | AQ14: =IF(AO14>=Resumen!$B$28,"Alto","Bajo") -> Bajo | AR14: =AP14&" Potencial / "&AQ14&" Share" -> Alto Potencial / Bajo Share | AS14: =IF(Q14="Sí",IF(AO14>=Resumen!$B$29,"Alto","Bajo"),"") -> Bajo | AT14: =IF(AS14<>"",AP14&" Potencial / "&AS14&" Share","") -> Alto Potencial / Bajo Share | AU14: =IF(AH14="","Sin dato",IF(AH14-AO14>Resumen!$B$6,"Sobre-exhibido",IF(AO14-AH14>Resumen!$B$6,"Sub-exhibido","En línea"))) -> Sobre-exhibido | AV14: =IF(AT14="","",IF(AT14="Alto Potencial / Bajo Share",1,IF(AT14="Alto Potencial / Alto Share",2,IF(AT14="Bajo Potencial / Alto Share",3,4)))) -> 1 | AW14: =IF(Q14="No","Sin competencia directa",IF(AV14=1,"1 - Foco Conquista (Alto Pot / Bajo Share)",IF(AV14=2,"2 - Foco Defensa (Alto Pot / Alto Share)",IF(AV14=3,"3 - Monitoreo (Bajo Pot / Alto Share)","4 - Baja Prioridad (Bajo Pot / Bajo Share)")))) -> 1 - Foco Conquista (Alto Pot / Bajo Share) | AX14: =IF(OR(IFERROR(AND(W14<>"",Y14<>"",Y14-W14>Resumen!$B$8),FALSE()),IFERROR(AND(X14<>"",Y14<>"",Y14-X14>Resumen!$B$8),FALSE())),MAX(IF(IFERROR(AND(W14<>"",Y14<>"",Y14-W14>Resumen!$B$8),FALSE()),Y14-W14,0),IF(IFERROR(AND(X14<>"",Y14<>"",Y14-X14>Resumen!$B$8),FALSE()),Y14-X14,0)),"") -> 0.10666667 | AY14: =IF(OR(IFERROR(AND(W14<>"",Y14<>"",Y14-W14>Resumen!$B$8),FALSE()),IFERROR(AND(X14<>"",Y14<>"",Y14-X14>Resumen!$B$8),FALSE())),TRIM("Lays tiene mayor markup que "&IF(IFERROR(AND(W14<>"",Y14<>"",Y14-W14>Resumen!$B$8),FALSE()),"Quento ","")&IF(IFERROR(AND(X14<>"",Y14<>"",Y14-X14>Resumen!$B$8),FALSE()),"Julicroc ","")&"en este PDV"),"") -> Lays tiene mayor markup que Julicroc en este PDV | AZ14: =IF(COUNTIF('Plan Pehuamar - Lista'!$A$2:$A$167,A14)>0,"Sí","No") -> Sí | BA14: =IF(COUNTIF('Plan Combo 9+1'!$A$2:$A$226,A14)>0,"Sí","No") -> No | BB14: =IF(AH14="","No",IF(BA14="Sí",IF((AO14-AH14)>Resumen!$B$6,"Sí","No"),IF((AO14-AH14)>=Resumen!$B$132,"Sí","No"))) -> No | BC14: =IF(AND(N14="Sí",AL14="Sí",AI14=0),"Sí","No") -> No | BD14: =IF(COUNTIF('Plan 9+1 (con Pehuamar)'!$A$2:$A$227,A14)>0,"Sí","No") -> Sí
A15: 400996 | B15: 1 | C15: 101 | D15: Lunes | E15: MERILES ANDREA SOLEDAD | F15: Autoservicio Tradicional | G15: Santa Fe | H15: Conrado Pujol | I15: 15 | J15: 20 | K15: 30 | L15: =I15+J15 -> 35 | M15: =L15+K15 -> 65 | N15: =IF(I15>0,"Sí","No") -> Sí | O15: =IF(J15>0,"Sí","No") -> Sí | P15: =IF(K15>0,"Sí","No") -> Sí | Q15: =IF(OR(I15>0,J15>0),"Sí","No") -> Sí | R15: 1800 | S15: 2900 | T15: 1600 | U15: 2600 | V15: 3700 | W15: =IF(AND(I15>0,R15>0),(S15-R15)/R15,"") -> 0.61111111 | X15: =IF(AND(J15>0,T15>0),(U15-T15)/T15,"") -> 0.625 | Y15: =IF(AND(K15>0,V15>0),(V15-Resumen!$B$7)/Resumen!$B$7,"") -> 0.48 | Z15: =IF(AND(K15>0,I15>0,V15>0,S15>0),V15-S15,"") -> 800 | AA15: =IF(Z15<>"",Z15/S15,"") -> 0.27586207 | AB15: =IF(AND(K15>0,J15>0,V15>0,U15>0),V15-U15,"") -> 1100 | AC15: =IF(AB15<>"",AB15/U15,"") -> 0.42307692 | AD15: 5 | AE15: 3 | AF15: 3 | AG15: =AD15+AE15+AF15 -> 11 | AH15: =IF(AG15>0,AD15/AG15,"") -> 0.45454545 | AI15: 1 | AJ15: 0 | AK15: 0 | AL15: =IF(OR(AJ15>0,AK15>0),"Sí","No") -> No | AM15: Contado | AN15: Contado | AO15: =IF(M15>0,K15/M15,"") -> 0.46153846 | AP15: =IF(M15>=Resumen!$B$5,"Alto","Bajo") -> Alto | AQ15: =IF(AO15>=Resumen!$B$28,"Alto","Bajo") -> Alto | AR15: =AP15&" Potencial / "&AQ15&" Share" -> Alto Potencial / Alto Share | AS15: =IF(Q15="Sí",IF(AO15>=Resumen!$B$29,"Alto","Bajo"),"") -> Bajo | AT15: =IF(AS15<>"",AP15&" Potencial / "&AS15&" Share","") -> Alto Potencial / Bajo Share | AU15: =IF(AH15="","Sin dato",IF(AH15-AO15>Resumen!$B$6,"Sobre-exhibido",IF(AO15-AH15>Resumen!$B$6,"Sub-exhibido","En línea"))) -> En línea | AV15: =IF(AT15="","",IF(AT15="Alto Potencial / Bajo Share",1,IF(AT15="Alto Potencial / Alto Share",2,IF(AT15="Bajo Potencial / Alto Share",3,4)))) -> 1 | AW15: =IF(Q15="No","Sin competencia directa",IF(AV15=1,"1 - Foco Conquista (Alto Pot / Bajo Share)",IF(AV15=2,"2 - Foco Defensa (Alto Pot / Alto Share)",IF(AV15=3,"3 - Monitoreo (Bajo Pot / Alto Share)","4 - Baja Prioridad (Bajo Pot / Bajo Share)")))) -> 1 - Foco Conquista (Alto Pot / Bajo Share) | AX15: =IF(OR(IFERROR(AND(W15<>"",Y15<>"",Y15-W15>Resumen!$B$8),FALSE()),IFERROR(AND(X15<>"",Y15<>"",Y15-X15>Resumen!$B$8),FALSE())),MAX(IF(IFERROR(AND(W15<>"",Y15<>"",Y15-W15>Resumen!$B$8),FALSE()),Y15-W15,0),IF(IFERROR(AND(X15<>"",Y15<>"",Y15-X15>Resumen!$B$8),FALSE()),Y15-X15,0)),"") | AY15: =IF(OR(IFERROR(AND(W15<>"",Y15<>"",Y15-W15>Resumen!$B$8),FALSE()),IFERROR(AND(X15<>"",Y15<>"",Y15-X15>Resumen!$B$8),FALSE())),TRIM("Lays tiene mayor markup que "&IF(IFERROR(AND(W15<>"",Y15<>"",Y15-W15>Resumen!$B$8),FALSE()),"Quento ","")&IF(IFERROR(AND(X15<>"",Y15<>"",Y15-X15>Resumen!$B$8),FALSE()),"Julicroc ","")&"en este PDV"),"") | AZ15: =IF(COUNTIF('Plan Pehuamar - Lista'!$A$2:$A$167,A15)>0,"Sí","No") -> No | BA15: =IF(COUNTIF('Plan Combo 9+1'!$A$2:$A$226,A15)>0,"Sí","No") -> No | BB15: =IF(AH15="","No",IF(BA15="Sí",IF((AO15-AH15)>Resumen!$B$6,"Sí","No"),IF((AO15-AH15)>=Resumen!$B$132,"Sí","No"))) -> No | BC15: =IF(AND(N15="Sí",AL15="Sí",AI15=0),"Sí","No") -> No | BD15: =IF(COUNTIF('Plan 9+1 (con Pehuamar)'!$A$2:$A$227,A15)>0,"Sí","No") -> No
A16: 401002 | B16: 1 | C16: 101 | D16: Lunes | E16: GAMBOA FERNANDO RUBEN | F16: Rotiseria | G16: Santa Fe | H16: Conrado Pujol | I16: 20 | J16: 0 | K16: 20 | L16: =I16+J16 -> 20 | M16: =L16+K16 -> 40 | N16: =IF(I16>0,"Sí","No") -> Sí | O16: =IF(J16>0,"Sí","No") -> No | P16: =IF(K16>0,"Sí","No") -> Sí | Q16: =IF(OR(I16>0,J16>0),"Sí","No") -> Sí | R16: 1800 | S16: 3000 | V16: 3500 | W16: =IF(AND(I16>0,R16>0),(S16-R16)/R16,"") -> 0.66666667 | X16: =IF(AND(J16>0,T16>0),(U16-T16)/T16,"") | Y16: =IF(AND(K16>0,V16>0),(V16-Resumen!$B$7)/Resumen!$B$7,"") -> 0.4 | Z16: =IF(AND(K16>0,I16>0,V16>0,S16>0),V16-S16,"") -> 500 | AA16: =IF(Z16<>"",Z16/S16,"") -> 0.16666667 | AB16: =IF(AND(K16>0,J16>0,V16>0,U16>0),V16-U16,"") | AC16: =IF(AB16<>"",AB16/U16,"") | AD16: 5 | AE16: 4 | AF16: 0 | AG16: =AD16+AE16+AF16 -> 9 | AH16: =IF(AG16>0,AD16/AG16,"") -> 0.55555556 | AI16: 1 | AJ16: 0 | AK16: 0 | AL16: =IF(OR(AJ16>0,AK16>0),"Sí","No") -> No | AM16: Contado | AO16: =IF(M16>0,K16/M16,"") -> 0.5 | AP16: =IF(M16>=Resumen!$B$5,"Alto","Bajo") -> Alto | AQ16: =IF(AO16>=Resumen!$B$28,"Alto","Bajo") -> Alto | AR16: =AP16&" Potencial / "&AQ16&" Share" -> Alto Potencial / Alto Share | AS16: =IF(Q16="Sí",IF(AO16>=Resumen!$B$29,"Alto","Bajo"),"") -> Alto | AT16: =IF(AS16<>"",AP16&" Potencial / "&AS16&" Share","") -> Alto Potencial / Alto Share | AU16: =IF(AH16="","Sin dato",IF(AH16-AO16>Resumen!$B$6,"Sobre-exhibido",IF(AO16-AH16>Resumen!$B$6,"Sub-exhibido","En línea"))) -> Sobre-exhibido | AV16: =IF(AT16="","",IF(AT16="Alto Potencial / Bajo Share",1,IF(AT16="Alto Potencial / Alto Share",2,IF(AT16="Bajo Potencial / Alto Share",3,4)))) -> 2 | AW16: =IF(Q16="No","Sin competencia directa",IF(AV16=1,"1 - Foco Conquista (Alto Pot / Bajo Share)",IF(AV16=2,"2 - Foco Defensa (Alto Pot / Alto Share)",IF(AV16=3,"3 - Monitoreo (Bajo Pot / Alto Share)","4 - Baja Prioridad (Bajo Pot / Bajo Share)")))) -> 2 - Foco Defensa (Alto Pot / Alto Share) | AX16: =IF(OR(IFERROR(AND(W16<>"",Y16<>"",Y16-W16>Resumen!$B$8),FALSE()),IFERROR(AND(X16<>"",Y16<>"",Y16-X16>Resumen!$B$8),FALSE())),MAX(IF(IFERROR(AND(W16<>"",Y16<>"",Y16-W16>Resumen!$B$8),FALSE()),Y16-W16,0),IF(IFERROR(AND(X16<>"",Y16<>"",Y16-X16>Resumen!$B$8),FALSE()),Y16-X16,0)),"") | AY16: =IF(OR(IFERROR(AND(W16<>"",Y16<>"",Y16-W16>Resumen!$B$8),FALSE()),IFERROR(AND(X16<>"",Y16<>"",Y16-X16>Resumen!$B$8),FALSE())),TRIM("Lays tiene mayor markup que "&IF(IFERROR(AND(W16<>"",Y16<>"",Y16-W16>Resumen!$B$8),FALSE()),"Quento ","")&IF(IFERROR(AND(X16<>"",Y16<>"",Y16-X16>Resumen!$B$8),FALSE()),"Julicroc ","")&"en este PDV"),"") | AZ16: =IF(COUNTIF('Plan Pehuamar - Lista'!$A$2:$A$167,A16)>0,"Sí","No") -> No | BA16: =IF(COUNTIF('Plan Combo 9+1'!$A$2:$A$226,A16)>0,"Sí","No") -> No | BB16: =IF(AH16="","No",IF(BA16="Sí",IF((AO16-AH16)>Resumen!$B$6,"Sí","No"),IF((AO16-AH16)>=Resumen!$B$132,"Sí","No"))) -> No | BC16: =IF(AND(N16="Sí",AL16="Sí",AI16=0),"Sí","No") -> No | BD16: =IF(COUNTIF('Plan 9+1 (con Pehuamar)'!$A$2:$A$227,A16)>0,"Sí","No") -> No
A17: 401003 | B17: 1 | C17: 101 | D17: Lunes | E17: VILLANUEVA ALBERTO LUIS EDUARD | F17: Almacen/Despensa | G17: Santa Fe | H17: Conrado Pujol | I17: 0 | J17: 0 | K17: 0.4 | L17: =I17+J17 -> 0 | M17: =L17+K17 -> 0.4 | N17: =IF(I17>0,"Sí","No") -> No | O17: =IF(J17>0,"Sí","No") -> No | P17: =IF(K17>0,"Sí","No") -> Sí | Q17: =IF(OR(I17>0,J17>0),"Sí","No") -> No | W17: =IF(AND(I17>0,R17>0),(S17-R17)/R17,"") | X17: =IF(AND(J17>0,T17>0),(U17-T17)/T17,"") | Y17: =IF(AND(K17>0,V17>0),(V17-Resumen!$B$7)/Resumen!$B$7,"") | Z17: =IF(AND(K17>0,I17>0,V17>0,S17>0),V17-S17,"") | AA17: =IF(Z17<>"",Z17/S17,"") | AB17: =IF(AND(K17>0,J17>0,V17>0,U17>0),V17-U17,"") | AC17: =IF(AB17<>"",AB17/U17,"") | AD17: 0 | AE17: 0 | AF17: 0 | AG17: =AD17+AE17+AF17 -> 0 | AH17: =IF(AG17>0,AD17/AG17,"") | AI17: 0 | AJ17: 0 | AK17: 0 | AL17: =IF(OR(AJ17>0,AK17>0),"Sí","No") -> No | AO17: =IF(M17>0,K17/M17,"") -> 1 | AP17: =IF(M17>=Resumen!$B$5,"Alto","Bajo") -> Bajo | AQ17: =IF(AO17>=Resumen!$B$28,"Alto","Bajo") -> Alto | AR17: =AP17&" Potencial / "&AQ17&" Share" -> Bajo Potencial / Alto Share | AS17: =IF(Q17="Sí",IF(AO17>=Resumen!$B$29,"Alto","Bajo"),"") | AT17: =IF(AS17<>"",AP17&" Potencial / "&AS17&" Share","") | AU17: =IF(AH17="","Sin dato",IF(AH17-AO17>Resumen!$B$6,"Sobre-exhibido",IF(AO17-AH17>Resumen!$B$6,"Sub-exhibido","En línea"))) -> Sin dato | AV17: =IF(AT17="","",IF(AT17="Alto Potencial / Bajo Share",1,IF(AT17="Alto Potencial / Alto Share",2,IF(AT17="Bajo Potencial / Alto Share",3,4)))) | AW17: =IF(Q17="No","Sin competencia directa",IF(AV17=1,"1 - Foco Conquista (Alto Pot / Bajo Share)",IF(AV17=2,"2 - Foco Defensa (Alto Pot / Alto Share)",IF(AV17=3,"3 - Monitoreo (Bajo Pot / Alto Share)","4 - Baja Prioridad (Bajo Pot / Bajo Share)")))) -> Sin competencia directa | AX17: =IF(OR(IFERROR(AND(W17<>"",Y17<>"",Y17-W17>Resumen!$B$8),FALSE()),IFERROR(AND(X17<>"",Y17<>"",Y17-X17>Resumen!$B$8),FALSE())),MAX(IF(IFERROR(AND(W17<>"",Y17<>"",Y17-W17>Resumen!$B$8),FALSE()),Y17-W17,0),IF(IFERROR(AND(X17<>"",Y17<>"",Y17-X17>Resumen!$B$8),FALSE()),Y17-X17,0)),"") | AY17: =IF(OR(IFERROR(AND(W17<>"",Y17<>"",Y17-W17>Resumen!$B$8),FALSE()),IFERROR(AND(X17<>"",Y17<>"",Y17-X17>Resumen!$B$8),FALSE())),TRIM("Lays tiene mayor markup que "&IF(IFERROR(AND(W17<>"",Y17<>"",Y17-W17>Resumen!$B$8),FALSE()),"Quento ","")&IF(IFERROR(AND(X17<>"",Y17<>"",Y17-X17>Resumen!$B$8),FALSE()),"Julicroc ","")&"en este PDV"),"") | AZ17: =IF(COUNTIF('Plan Pehuamar - Lista'!$A$2:$A$167,A17)>0,"Sí","No") -> No | BA17: =IF(COUNTIF('Plan Combo 9+1'!$A$2:$A$226,A17)>0,"Sí","No") -> No | BB17: =IF(AH17="","No",IF(BA17="Sí",IF((AO17-AH17)>Resumen!$B$6,"Sí","No"),IF((AO17-AH17)>=Resumen!$B$132,"Sí","No"))) -> No | BC17: =IF(AND(N17="Sí",AL17="Sí",AI17=0),"Sí","No") -> No | BD17: =IF(COUNTIF('Plan 9+1 (con Pehuamar)'!$A$2:$A$227,A17)>0,"Sí","No") -> No
A18: 401004 | B18: 1 | C18: 101 | D18: Lunes | E18: YOSSEN ARIEL EDGARDO | F18: Almacen/Despensa | G18: Santa Fe | H18: Conrado Pujol | I18: 0 | J18: 0 | K18: 0.7 | L18: =I18+J18 -> 0 | M18: =L18+K18 -> 0.7 | N18: =IF(I18>0,"Sí","No") -> No | O18: =IF(J18>0,"Sí","No") -> No | P18: =IF(K18>0,"Sí","No") -> Sí | Q18: =IF(OR(I18>0,J18>0),"Sí","No") -> No | W18: =IF(AND(I18>0,R18>0),(S18-R18)/R18,"") | X18: =IF(AND(J18>0,T18>0),(U18-T18)/T18,"") | Y18: =IF(AND(K18>0,V18>0),(V18-Resumen!$B$7)/Resumen!$B$7,"") | Z18: =IF(AND(K18>0,I18>0,V18>0,S18>0),V18-S18,"") | AA18: =IF(Z18<>"",Z18/S18,"") | AB18: =IF(AND(K18>0,J18>0,V18>0,U18>0),V18-U18,"") | AC18: =IF(AB18<>"",AB18/U18,"") | AD18: 0 | AE18: 0 | AF18: 0 | AG18: =AD18+AE18+AF18 -> 0 | AH18: =IF(AG18>0,AD18/AG18,"") | AI18: 0 | AJ18: 0 | AK18: 0 | AL18: =IF(OR(AJ18>0,AK18>0),"Sí","No") -> No | AO18: =IF(M18>0,K18/M18,"") -> 1 | AP18: =IF(M18>=Resumen!$B$5,"Alto","Bajo") -> Bajo | AQ18: =IF(AO18>=Resumen!$B$28,"Alto","Bajo") -> Alto | AR18: =AP18&" Potencial / "&AQ18&" Share" -> Bajo Potencial / Alto Share | AS18: =IF(Q18="Sí",IF(AO18>=Resumen!$B$29,"Alto","Bajo"),"") | AT18: =IF(AS18<>"",AP18&" Potencial / "&AS18&" Share","") | AU18: =IF(AH18="","Sin dato",IF(AH18-AO18>Resumen!$B$6,"Sobre-exhibido",IF(AO18-AH18>Resumen!$B$6,"Sub-exhibido","En línea"))) -> Sin dato | AV18: =IF(AT18="","",IF(AT18="Alto Potencial / Bajo Share",1,IF(AT18="Alto Potencial / Alto Share",2,IF(AT18="Bajo Potencial / Alto Share",3,4)))) | AW18: =IF(Q18="No","Sin competencia directa",IF(AV18=1,"1 - Foco Conquista (Alto Pot / Bajo Share)",IF(AV18=2,"2 - Foco Defensa (Alto Pot / Alto Share)",IF(AV18=3,"3 - Monitoreo (Bajo Pot / Alto Share)","4 - Baja Prioridad (Bajo Pot / Bajo Share)")))) -> Sin competencia directa | AX18: =IF(OR(IFERROR(AND(W18<>"",Y18<>"",Y18-W18>Resumen!$B$8),FALSE()),IFERROR(AND(X18<>"",Y18<>"",Y18-X18>Resumen!$B$8),FALSE())),MAX(IF(IFERROR(AND(W18<>"",Y18<>"",Y18-W18>Resumen!$B$8),FALSE()),Y18-W18,0),IF(IFERROR(AND(X18<>"",Y18<>"",Y18-X18>Resumen!$B$8),FALSE()),Y18-X18,0)),"") | AY18: =IF(OR(IFERROR(AND(W18<>"",Y18<>"",Y18-W18>Resumen!$B$8),FALSE()),IFERROR(AND(X18<>"",Y18<>"",Y18-X18>Resumen!$B$8),FALSE())),TRIM("Lays tiene mayor markup que "&IF(IFERROR(AND(W18<>"",Y18<>"",Y18-W18>Resumen!$B$8),FALSE()),"Quento ","")&IF(IFERROR(AND(X18<>"",Y18<>"",Y18-X18>Resumen!$B$8),FALSE()),"Julicroc ","")&"en este PDV"),"") | AZ18: =IF(COUNTIF('Plan Pehuamar - Lista'!$A$2:$A$167,A18)>0,"Sí","No") -> No | BA18: =IF(COUNTIF('Plan Combo 9+1'!$A$2:$A$226,A18)>0,"Sí","No") -> No | BB18: =IF(AH18="","No",IF(BA18="Sí",IF((AO18-AH18)>Resumen!$B$6,"Sí","No"),IF((AO18-AH18)>=Resumen!$B$132,"Sí","No"))) -> No | BC18: =IF(AND(N18="Sí",AL18="Sí",AI18=0),"Sí","No") -> No | BD18: =IF(COUNTIF('Plan 9+1 (con Pehuamar)'!$A$2:$A$227,A18)>0,"Sí","No") -> No
A19: 401010 | B19: 1 | C19: 101 | D19: Lunes | E19: SEDRAN SANTOS FABIAN | F19: Panaderia | G19: Santa Fe | H19: Conrado Pujol | I19: 0 | J19: 0 | K19: 0.5 | L19: =I19+J19 -> 0 | M19: =L19+K19 -> 0.5 | N19: =IF(I19>0,"Sí","No") -> No | O19: =IF(J19>0,"Sí","No") -> No | P19: =IF(K19>0,"Sí","No") -> Sí | Q19: =IF(OR(I19>0,J19>0),"Sí","No") -> No | W19: =IF(AND(I19>0,R19>0),(S19-R19)/R19,"") | X19: =IF(AND(J19>0,T19>0),(U19-T19)/T19,"") | Y19: =IF(AND(K19>0,V19>0),(V19-Resumen!$B$7)/Resumen!$B$7,"") | Z19: =IF(AND(K19>0,I19>0,V19>0,S19>0),V19-S19,"") | AA19: =IF(Z19<>"",Z19/S19,"") | AB19: =IF(AND(K19>0,J19>0,V19>0,U19>0),V19-U19,"") | AC19: =IF(AB19<>"",AB19/U19,"") | AD19: 0 | AE19: 0 | AF19: 0 | AG19: =AD19+AE19+AF19 -> 0 | AH19: =IF(AG19>0,AD19/AG19,"") | AI19: 0 | AJ19: 0 | AK19: 0 | AL19: =IF(OR(AJ19>0,AK19>0),"Sí","No") -> No | AO19: =IF(M19>0,K19/M19,"") -> 1 | AP19: =IF(M19>=Resumen!$B$5,"Alto","Bajo") -> Bajo | AQ19: =IF(AO19>=Resumen!$B$28,"Alto","Bajo") -> Alto | AR19: =AP19&" Potencial / "&AQ19&" Share" -> Bajo Potencial / Alto Share | AS19: =IF(Q19="Sí",IF(AO19>=Resumen!$B$29,"Alto","Bajo"),"") | AT19: =IF(AS19<>"",AP19&" Potencial / "&AS19&" Share","") | AU19: =IF(AH19="","Sin dato",IF(AH19-AO19>Resumen!$B$6,"Sobre-exhibido",IF(AO19-AH19>Resumen!$B$6,"Sub-exhibido","En línea"))) -> Sin dato | AV19: =IF(AT19="","",IF(AT19="Alto Potencial / Bajo Share",1,IF(AT19="Alto Potencial / Alto Share",2,IF(AT19="Bajo Potencial / Alto Share",3,4)))) | AW19: =IF(Q19="No","Sin competencia directa",IF(AV19=1,"1 - Foco Conquista (Alto Pot / Bajo Share)",IF(AV19=2,"2 - Foco Defensa (Alto Pot / Alto Share)",IF(AV19=3,"3 - Monitoreo (Bajo Pot / Alto Share)","4 - Baja Prioridad (Bajo Pot / Bajo Share)")))) -> Sin competencia directa | AX19: =IF(OR(IFERROR(AND(W19<>"",Y19<>"",Y19-W19>Resumen!$B$8),FALSE()),IFERROR(AND(X19<>"",Y19<>"",Y19-X19>Resumen!$B$8),FALSE())),MAX(IF(IFERROR(AND(W19<>"",Y19<>"",Y19-W19>Resumen!$B$8),FALSE()),Y19-W19,0),IF(IFERROR(AND(X19<>"",Y19<>"",Y19-X19>Resumen!$B$8),FALSE()),Y19-X19,0)),"") | AY19: =IF(OR(IFERROR(AND(W19<>"",Y19<>"",Y19-W19>Resumen!$B$8),FALSE()),IFERROR(AND(X19<>"",Y19<>"",Y19-X19>Resumen!$B$8),FALSE())),TRIM("Lays tiene mayor markup que "&IF(IFERROR(AND(W19<>"",Y19<>"",Y19-W19>Resumen!$B$8),FALSE()),"Quento ","")&IF(IFERROR(AND(X19<>"",Y19<>"",Y19-X19>Resumen!$B$8),FALSE()),"Julicroc ","")&"en este PDV"),"") | AZ19: =IF(COUNTIF('Plan Pehuamar - Lista'!$A$2:$A$167,A19)>0,"Sí","No") -> No | BA19: =IF(COUNTIF('Plan Combo 9+1'!$A$2:$A$226,A19)>0,"Sí","No") -> No | BB19: =IF(AH19="","No",IF(BA19="Sí",IF((AO19-AH19)>Resumen!$B$6,"Sí","No"),IF((AO19-AH19)>=Resumen!$B$132,"Sí","No"))) -> No | BC19: =IF(AND(N19="Sí",AL19="Sí",AI19=0),"Sí","No") -> No | BD19: =IF(COUNTIF('Plan 9+1 (con Pehuamar)'!$A$2:$A$227,A19)>0,"Sí","No") -> No
